Workbook

Sheet Start Here
A1: CM Family Rhythm Planner v9
A3: Workflow
A4: 1 | B4: =HYPERLINK("https://docs.google.com/spreadsheets/d/1Oo1LHNHUNq0Yv_zGqT-GDn0G_Bz1PGYKe93-p2G2cbg/edit#gid=1207041131&range=A1","Setup") -> Setup | C4: Add active students, their Forms, and the groups your family actually uses.
A5: 2 | B5: =HYPERLINK("https://docs.google.com/spreadsheets/d/1Oo1LHNHUNq0Yv_zGqT-GDn0G_Bz1PGYKe93-p2G2cbg/edit#gid=480972818&range=A1","School Calendar") -> School Calendar | C5: Set the school-year dates, terms, breaks, exceptions, and exam weeks.
A6: 3 | B6: =HYPERLINK("https://docs.google.com/spreadsheets/d/1Oo1LHNHUNq0Yv_zGqT-GDn0G_Bz1PGYKe93-p2G2cbg/edit#gid=613521042&range=A1","Family Map") -> Family Map | C6: Review the Charlotte Mason feast. Turn strands on or off, rename them, or add a custom strand only when needed.
A7: 4 | B7: =HYPERLINK("https://docs.google.com/spreadsheets/d/1Oo1LHNHUNq0Yv_zGqT-GDn0G_Bz1PGYKe93-p2G2cbg/edit#gid=201462614&range=A1","Strand Placement") -> Strand Placement | C7: Build family and group loops, then place shared or genuinely rotating strands.
A8: 5 | B8: =HYPERLINK("https://docs.google.com/spreadsheets/d/1Oo1LHNHUNq0Yv_zGqT-GDn0G_Bz1PGYKe93-p2G2cbg/edit#gid=1199004913&range=A1","Student Work") -> Student Work | C8: Place fixed individual work under Table Work with Mom or Independent Work.
A9: 6 | B9: =HYPERLINK("https://docs.google.com/spreadsheets/d/1Oo1LHNHUNq0Yv_zGqT-GDn0G_Bz1PGYKe93-p2G2cbg/edit#gid=1134758644&range=A1","Resource Planner") -> Resource Planner | C9: Add books, courses, and other resources. Use Focus Strand to see what is already entered and what comes next.
A10: 7 | B10: =HYPERLINK("https://docs.google.com/spreadsheets/d/1Oo1LHNHUNq0Yv_zGqT-GDn0G_Bz1PGYKe93-p2G2cbg/edit#gid=985604979&range=A1","Term Grid") -> Term Grid | C10: Review the term for gaps, overload, pacing, and resource sequencing.
A11: 8 | B11: =HYPERLINK("https://docs.google.com/spreadsheets/d/1Oo1LHNHUNq0Yv_zGqT-GDn0G_Bz1PGYKe93-p2G2cbg/edit#gid=1134222427&range=A1","Daily Rhythm") -> Daily Rhythm | C11: Shape the normal day around loops, table work, independent work, outside commitments, and Mom’s attention.
A12: 9 | B12: =HYPERLINK("https://docs.google.com/spreadsheets/d/1Oo1LHNHUNq0Yv_zGqT-GDn0G_Bz1PGYKe93-p2G2cbg/edit#gid=1509443170&range=A1","Assignment View") -> Assignment View | C12: Filter, review, and print generated assignments by person, subject, strand, resource, date, or status.
A13: 10 | B13: =HYPERLINK("https://docs.google.com/spreadsheets/d/1Oo1LHNHUNq0Yv_zGqT-GDn0G_Bz1PGYKe93-p2G2cbg/edit#gid=1423517889&range=A1","What's Next") -> What's Next | C13: Use the daily dashboard to see the next incomplete work after the plan is built.
A14: Plot line | B14: See the feast. Place the strands. Plan the resources. View the term. Shape the day. Live the plan.
A15: Note | B15: Generated Plan and the helper sheets are workbook machinery. Most parents will not need to open or edit them.

Sheet Setup
A1: Setup
A2: Step 1 • Add active students, choose each child’s Form, and create only the groups your family will use. Done when every active child has a Form and your real groups are checked. Next: School Calendar.
A4: Students | M4: Dropdown Lists | S4: Active People + Groups Helper
A5: Use? | B5: Student | C5: Color | D5: Form | E5: Grade/Age | F5: Notes | G5: Mon | H5: Tue | I5: Wed | J5: Thu | K5: Fri | M5: Check | N5: Colors | O5: Modes | P5: Mom Roles | Q5: Unit Types | S5: Dropdown Value | T5: Source | U5: Note
A6: TRUE | B6: Lucy | C6: Pink | D6: Form III | E6: 7th | G6: TRUE | H6: TRUE | I6: TRUE | J6: FALSE | K6: TRUE | M6: ☑ | N6: Pink | O6: Group | P6: Mom-led | Q6: Chapter | S6: =IF(OR(A6=TRUE,A6="☑"),B6,"") -> Lucy | T6: Student
A7: TRUE | B7: Kayla | C7: Purple | D7: Form II | E7: 3rd | G7: TRUE | H7: TRUE | I7: TRUE | J7: FALSE | K7: TRUE | M7: ☐ | N7: Purple | O7: Individual | P7: Start together | Q7: Lesson | S7: =IF(OR(A7=TRUE,A7="☑"),B7,"") -> Kayla | T7: Student
A8: TRUE | B8: Charis | C8: Aqua | D8: Form I | E8: 1st | G8: TRUE | H8: TRUE | I8: TRUE | J8: FALSE | K8: TRUE | N8: Aqua | O8: Outside / Co-op | P8: Check-in | Q8: Page | S8: =IF(OR(A8=TRUE,A8="☑"),B8,"") -> Charis | T8: Student
A9: TRUE | B9: Jeremiah | C9: Gold | D9: Form IV | E9: 10th | G9: TRUE | H9: FALSE | I9: TRUE | J9: FALSE | K9: TRUE | N9: Gold | P9: Independent | Q9: Week | S9: =IF(OR(A9=TRUE,A9="☑"),B9,"") -> Jeremiah | T9: Student
A10: FALSE | B10: Child 5 | C10: Blue | D10: Form V-VI | G10: FALSE | H10: FALSE | I10: FALSE | J10: FALSE | K10: FALSE | N10: Blue | P10: Outside teacher | Q10: Story | S10: =IF(OR(A10=TRUE,A10="☑"),B10,"") | T10: Student
A11: FALSE | B11: Child 6 | C11: Green | G11: FALSE | H11: FALSE | I11: FALSE | J11: FALSE | K11: FALSE | N11: Green | Q11: Unit | S11: =IF(OR(A11=TRUE,A11="☑"),B11,"") | T11: Student
A12: FALSE | B12: Child 7 | C12: Coral | G12: FALSE | H12: FALSE | I12: FALSE | J12: FALSE | K12: FALSE | N12: Coral | Q12: Reading | S12: =IF(OR(A12=TRUE,A12="☑"),B12,"") | T12: Student
A13: FALSE | B13: Child 8 | C13: Gray | G13: FALSE | H13: FALSE | I13: FALSE | J13: FALSE | K13: FALSE | N13: Gray | S13: =IF(OR(A13=TRUE,A13="☑"),B13,"") | T13: Student
T14: Built-in | U14: Use when strand happens separately for each active student
A15: Student Groups | T15: Built-in | U15: Use for outside/co-op or optional blocks
A16: Use? | B16: Group Name | C16: Lucy | D16: Kayla | E16: Charis | F16: Jeremiah | G16: Child 5 | H16: Child 6 | I16: Child 7 | J16: Child 8 | K16: Notes | S16: =IF(OR(A17=TRUE,A17="☑"),B17,"") -> Everyone | T16: Group
A17: TRUE | B17: Everyone | C17: TRUE | D17: TRUE | E17: TRUE | F17: TRUE | G17: FALSE | H17: FALSE | I17: FALSE | J17: FALSE | K17: family subjects | S17: =IF(OR(A18=TRUE,A18="☑"),B18,"") -> Little Girls | T17: Group
A18: TRUE | B18: Little Girls | C18: FALSE | D18: TRUE | E18: TRUE | F18: FALSE | G18: FALSE | H18: FALSE | I18: FALSE | J18: FALSE | S18: =IF(OR(A19=TRUE,A19="☑"),B19,"") -> All the Girls | T18: Group
A19: TRUE | B19: All the Girls | C19: TRUE | D19: TRUE | E19: TRUE | F19: FALSE | G19: FALSE | H19: FALSE | I19: FALSE | J19: FALSE | S19: =IF(OR(A20=TRUE,A20="☑"),B20,"") -> Older Students | T19: Group
A20: TRUE | B20: Older Students | C20: TRUE | D20: FALSE | E20: FALSE | F20: TRUE | G20: FALSE | H20: FALSE | I20: FALSE | J20: FALSE | S20: =IF(OR(A21=TRUE,A21="☑"),B21,"") | T20: Group
A21: FALSE | B21: Custom Group 1 | C21: FALSE | D21: FALSE | E21: FALSE | F21: FALSE | G21: FALSE | H21: FALSE | I21: FALSE | J21: FALSE | S21: =IF(OR(A22=TRUE,A22="☑"),B22,"") | T21: Group
A22: FALSE | B22: Custom Group 2 | C22: FALSE | D22: FALSE | E22: FALSE | F22: FALSE | G22: FALSE | H22: FALSE | I22: FALSE | J22: FALSE | S22: =IF(OR(A23=TRUE,A23="☑"),B23,"") | T22: Group
A23: FALSE | B23: Custom Group 3 | C23: FALSE | D23: FALSE | E23: FALSE | F23: FALSE | G23: FALSE | H23: FALSE | I23: FALSE | J23: FALSE | S23: =IF(OR(A24=TRUE,A24="☑"),B24,"") | T23: Group
A24: FALSE | B24: Custom Group 4 | C24: FALSE | D24: FALSE | E24: FALSE | F24: FALSE | G24: FALSE | H24: FALSE | I24: FALSE | J24: FALSE | S24: =IF(OR(A25=TRUE,A25="☑"),B25,"") | T24: Group
A25: FALSE | B25: Custom Group 5 | C25: FALSE | D25: FALSE | E25: FALSE | F25: FALSE | G25: FALSE | H25: FALSE | I25: FALSE | J25: FALSE | S25: =IF(OR(A26=TRUE,A26="☑"),B26,"") | T25: Group
A26: FALSE | B26: Custom Group 6 | C26: FALSE | D26: FALSE | E26: FALSE | F26: FALSE | G26: FALSE | H26: FALSE | I26: FALSE | J26: FALSE
A28: School Year Settings
A29: School Year Start Date | B29: ='School Calendar'!B5 -> 46244 | C29: Edit on School Calendar
A30: Planned School Year Length | B30: ='School Calendar'!B6 -> 36 | C30: Edit on School Calendar
A31: Number of Terms | B31: ='School Calendar'!B7 -> 3 | C31: Edit on School Calendar
A32: Weeks per Term | B32: ='School Calendar'!B8 -> 12 | C32: Edit on School Calendar
A33: Use Exam Weeks? | B33: ='School Calendar'!B9 -> Yes | C33: Edit on School Calendar
A34: Default School Days | B34: ='School Calendar'!B12 -> Monday, Tuesday, Wednesday, Thursday, Friday | C34: Edit on School Calendar
A36: Active Forms, automatic from student form choices.
A37: Status | B37: Form / Stage | C37: How this is determined
A38: ="☑" -> ☑ | B38: All Together | C38: Always active for family subjects
A39: =IF(SUMPRODUCT(($D$6:$D$13=B39)*((($A$6:$A$13="☑")+($A$6:$A$13=TRUE))>0))>0,"☑","☐") -> ☑ | B39: Form I | C39: Active when an active student uses this form
A40: =IF(SUMPRODUCT(($D$6:$D$13=B40)*((($A$6:$A$13="☑")+($A$6:$A$13=TRUE))>0))>0,"☑","☐") -> ☑ | B40: Form II | C40: Active when an active student uses this form
A41: =IF(SUMPRODUCT(($D$6:$D$13=B41)*((($A$6:$A$13="☑")+($A$6:$A$13=TRUE))>0))>0,"☑","☐") -> ☑ | B41: Form III | C41: Active when an active student uses this form
A42: =IF(SUMPRODUCT(($D$6:$D$13=B42)*((($A$6:$A$13="☑")+($A$6:$A$13=TRUE))>0))>0,"☑","☐") -> ☑ | B42: Form IV | C42: Active when an active student uses this form
A43: =IF(SUMPRODUCT(($D$6:$D$13=B43)*((($A$6:$A$13="☑")+($A$6:$A$13=TRUE))>0))>0,"☑","☐") -> ☐ | B43: Form V-VI | C43: Active when an active student uses this form
...

Sheet School Calendar
A1: School Calendar
A2: Step 2 • Set the school year and add breaks, holidays, recurring co-op days, appointments, or other exceptions below. A full week with no counted school days does not use a term week; exam week moves to the next counted school week. Next: Family Map.
A4: 1. School Year Setup | H4: 3. Advanced Attendance Settings | N4: Day Type Options | O4: School Day Options | P4: Rhythm Options
A5: School Year Start Date | B5: 46244 | J5: Most families can leave this Monday-Friday for attendance purposes. | N5: Break | O5: Yes | P5: Skip
A6: Planned School Year Length | B6: 36 | H6: Day | I6: Use? | J6: Use Calendar Exceptions to mark co-op days, park days, short days, breaks, holidays, or travel. | N6: Holiday | O6: No | P6: Normal rhythm
A7: Number of Terms | B7: 3 | H7: Monday | I7: TRUE | J7: Daily Rhythm controls what actually happens at home. | N7: Co-op Day | O7: Partial | P7: Short rhythm
A8: Weeks per Term | B8: 12 | H8: Tuesday | I8: TRUE | N8: Park Day | P8: Outside / co-op only
A9: Use Exam Weeks? | B9: Yes | H9: Wednesday | I9: TRUE | J9: Automatic weekday summary | N9: Nature Day | P9: Nature / park day
A10: Calculated Last School Day | B10: =IFERROR(LOOKUP(2,1/(($H$44:$H$408=TRUE)*($J$44:$J$408=$B$6)),$A$44:$A$408),"") | H10: Thursday | I10: TRUE | J10: =$B$12 -> Monday, Tuesday, Wednesday, Thursday, Friday | N10: Appointment / Short Day | P10: Gather + daily skills only
A11: Manual Last Day Override, optional | H11: Friday | I11: TRUE | N11: Travel Day | P11: Custom
B12: =TEXTJOIN(", ",TRUE,IF(I7,H7,""),IF(I8,H8,""),IF(I9,H9,""),IF(I10,H10,""),IF(I11,H11,""),IF(I12,H12,""),IF(I13,H13,"")) -> Monday, Tuesday, Wednesday, Thursday, Friday | H12: Saturday | I12: FALSE
A13: Add breaks, holidays, recurring co-op days, park days, short days, travel, or other exceptions here. Tip: Double-click a Start Date or End Date cell to open the calendar. | H13: Sunday | I13: FALSE | N13: Other
A14: 2. Calendar Exceptions
A15: Start Date | B15: End Date | C15: Applies On | D15: Day Type | E15: Name / Details, optional | F15: Counts as School Day? | G15: Rhythm Adjustment
F17: FALSE
F18: FALSE
F19: FALSE
F20: FALSE
F21: FALSE
F22: FALSE
F23: FALSE
F24: FALSE
F25: FALSE
F26: FALSE
F27: FALSE
F28: FALSE
... F35: FALSE
A36: Enter breaks, holidays, recurring weekday exceptions, appointments, travel days, or other calendar changes here.
A41: 4. Generated Calendar, formula output
A42: This table powers future scheduling. Most users do not need to edit it.
A43: Date | B43: Day of Week | C43: Default School Day? | D43: Day Type | E43: Name / Details | F43: Counts as School Day? | G43: Rhythm Adjustment | H43: School Day? | I43: School Day Number | J43: School Week | K43: Term | L43: Term Week | M43: Exam Week? | N43: Week Start Helper | O43: Counted School Week? | Q43: Exception Row Helper
A44: =$B$5 -> 46244 | B44: =TEXT(A44,"dddd") -> Monday | C44: =IFERROR(INDEX($I$7:$I$13,MATCH(B44,$H$7:$H$13,0)),FALSE) -> TRUE | D44: =IF($Q44=0,"",INDEX($D$16:$D$35,$Q44-ROW($A$16)+1)) | E44: =IF($Q44=0,"",INDEX($E$16:$E$35,$Q44-ROW($A$16)+1)) | F44: =IF($Q44=0,"",INDEX($F$16:$F$35,$Q44-ROW($A$16)+1)) | G44: =IF($Q44=0,"",INDEX($G$16:$G$35,$Q44-ROW($A$16)+1)) | H44: =IF(F44="",C44,F44) -> TRUE | I44: =IF(H44,COUNTIF($H$44:H44,TRUE),"") -> 1 | J44: =IFERROR(__xludf.DUMMYFUNCTION("IF(O44,LET(w,IFERROR(MATCH(N44,UNIQUE(FILTER($N$44:$N$408,$O$44:$O$408=TRUE)),0),""""),IF(OR(w="""",w>$B$6),"""",w)),"""")"),1.0) -> 1 | K44: =IF(J44="","","Term "&MIN($B$7,ROUNDUP(J44/$B$8,0))) -> Term 1 | L44: =IF(J44="","",MOD(J44-1,$B$8)+1) -> 1 | M44: =IF(J44="",FALSE,AND($B$9="Yes",MOD(J44,$B$8)=0)) -> FALSE | N44: =A44-WEEKDAY(A44,2)+1 -> 46244 | O44: =SUMPRODUCT(($N$44:$N$408=N44)*(WEEKDAY($A$44:$A$408,2)<=5)*--($H$44:$H$408=TRUE))>0 -> TRUE | Q44: =LET(base,IFERROR(INT(LOG(SUMPRODUCT(($A$16:$A$35<>"")*($B$16:$B$35<>"")*(A44>=$A$16:$A$35)*(A44<=$B$16:$B$35)*--((($C$16:$C$35="All dates")+($C$16:$C$35=B44))>0),{1;2;4;8;16;32;64;128;256;512;1024;2048;4096;8192;16384;32768;65536;131072;262144;524288}),2))+16,0),breakRow,IFERROR(INT(LOG(SUMPRODUCT(($A$16:$A$35<>"")*($B$16:$B$35<>"")*(A44>=$A$16:$A$35)*(A44<=$B$16:$B$35)*--((($C$16:$C$35="All dates")+($C$16:$C$35=B44))>0)*($F$16:$F$35=FALSE)*($F$16:$F$35<>"")*--((($D$16:$D$35="Break")+($D$16:$D$35="Holiday"))>0),{1;2;4;8;16;32;64;128;256;512;1024;2048;4096;8192;16384;32768;65536;131072;262144;524288}),2))+16,0),baseStatus,IF(base=0,"",INDEX($F$16:$F$35,base-15)),singleRow,IFERROR(INT(LOG(SUMPRODUCT(($A$16:$A$35<>"")*($B$16:$B$35<>"")*(A44>=$A$16:$A$35)*(A44<=$B$16:$B$35)*--((($C$16:$C$35="All dates")+($C$16:$C$35=B44))>0)*($A$16:$A$35=$B$16:$B$35)*($F$16:$F$35=baseStatus),{1;2;4;8;16;32;64;128;256;512;1024;2048;4096;8192;16384;32768;65536;131072;262144;524288}),2))+16,0),IF(breakRow>0,breakRow,IF(singleRow>0,singleRow,base))) -> 0
A45: =A44+1 -> 46245 | B45: =TEXT(A45,"dddd") -> Tuesday | C45: =IFERROR(INDEX($I$7:$I$13,MATCH(B45,$H$7:$H$13,0)),FALSE) -> TRUE | D45: =IF($Q45=0,"",INDEX($D$16:$D$35,$Q45-ROW($A$16)+1)) | E45: =IF($Q45=0,"",INDEX($E$16:$E$35,$Q45-ROW($A$16)+1)) | F45: =IF($Q45=0,"",INDEX($F$16:$F$35,$Q45-ROW($A$16)+1)) | G45: =IF($Q45=0,"",INDEX($G$16:$G$35,$Q45-ROW($A$16)+1)) | H45: =IF(F45="",C45,F45) -> TRUE | I45: =IF(H45,COUNTIF($H$44:H45,TRUE),"") -> 2 | J45: =IFERROR(__xludf.DUMMYFUNCTION("IF(O45,LET(w,IFERROR(MATCH(N45,UNIQUE(FILTER($N$44:$N$408,$O$44:$O$408=TRUE)),0),""""),IF(OR(w="""",w>$B$6),"""",w)),"""")"),1.0) -> 1 | K45: =IF(J45="","","Term "&MIN($B$7,ROUNDUP(J45/$B$8,0))) -> Term 1 | L45: =IF(J45="","",MOD(J45-1,$B$8)+1) -> 1 | M45: =IF(J45="",FALSE,AND($B$9="Yes",MOD(J45,$B$8)=0)) -> FALSE | N45: =A45-WEEKDAY(A45,2)+1 -> 46244 | O45: =SUMPRODUCT(($N$44:$N$408=N45)*(WEEKDAY($A$44:$A$408,2)<=5)*--($H$44:$H$408=TRUE))>0 -> TRUE | Q45: =LET(base,IFERROR(INT(LOG(SUMPRODUCT(($A$16:$A$35<>"")*($B$16:$B$35<>"")*(A45>=$A$16:$A$35)*(A45<=$B$16:$B$35)*--((($C$16:$C$35="All dates")+($C$16:$C$35=B45))>0),{1;2;4;8;16;32;64;128;256;512;1024;2048;4096;8192;16384;32768;65536;131072;262144;524288}),2))+16,0),breakRow,IFERROR(INT(LOG(SUMPRODUCT(($A$16:$A$35<>"")*($B$16:$B$35<>"")*(A45>=$A$16:$A$35)*(A45<=$B$16:$B$35)*--((($C$16:$C$35="All dates")+($C$16:$C$35=B45))>0)*($F$16:$F$35=FALSE)*($F$16:$F$35<>"")*--((($D$16:$D$35="Break")+($D$16:$D$35="Holiday"))>0),{1;2;4;8;16;32;64;128;256;512;1024;2048;4096;8192;16384;32768;65536;131072;262144;524288}),2))+16,0),baseStatus,IF(base=0,"",INDEX($F$16:$F$35,base-15)),singleRow,IFERROR(INT(LOG(SUMPRODUCT(($A$16:$A$35<>"")*($B$16:$B$35<>"")*(A45>=$A$16:$A$35)*(A45<=$B$16:$B$35)*--((($C$16:$C$35="All dates")+($C$16:$C$35=B45))>0)*($A$16:$A$35=$B$16:$B$35)*($F$16:$F$35=baseStatus),{1;2;4;8;16;32;64;128;256;512;1024;2048;4096;8192;16384;32768;65536;131072;262144;524288}),2))+16,0),IF(breakRow>0,breakRow,IF(singleRow>0,singleRow,base))) -> 0
A46: =A45+1 -> 46246 | B46: =TEXT(A46,"dddd") -> Wednesday | C46: =IFERROR(INDEX($I$7:$I$13,MATCH(B46,$H$7:$H$13,0)),FALSE) -> TRUE | D46: =IF($Q46=0,"",INDEX($D$16:$D$35,$Q46-ROW($A$16)+1)) | E46: =IF($Q46=0,"",INDEX($E$16:$E$35,$Q46-ROW($A$16)+1)) | F46: =IF($Q46=0,"",INDEX($F$16:$F$35,$Q46-ROW($A$16)+1)) | G46: =IF($Q46=0,"",INDEX($G$16:$G$35,$Q46-ROW($A$16)+1)) | H46: =IF(F46="",C46,F46) -> TRUE | I46: =IF(H46,COUNTIF($H$44:H46,TRUE),"") -> 3 | J46: =IFERROR(__xludf.DUMMYFUNCTION("IF(O46,LET(w,IFERROR(MATCH(N46,UNIQUE(FILTER($N$44:$N$408,$O$44:$O$408=TRUE)),0),""""),IF(OR(w="""",w>$B$6),"""",w)),"""")"),1.0) -> 1 | K46: =IF(J46="","","Term "&MIN($B$7,ROUNDUP(J46/$B$8,0))) -> Term 1 | L46: =IF(J46="","",MOD(J46-1,$B$8)+1) -> 1 | M46: =IF(J46="",FALSE,AND($B$9="Yes",MOD(J46,$B$8)=0)) -> FALSE | N46: =A46-WEEKDAY(A46,2)+1 -> 46244 | O46: =SUMPRODUCT(($N$44:$N$408=N46)*(WEEKDAY($A$44:$A$408,2)<=5)*--($H$44:$H$408=TRUE))>0 -> TRUE | Q46: =LET(base,IFERROR(INT(LOG(SUMPRODUCT(($A$16:$A$35<>"")*($B$16:$B$35<>"")*(A46>=$A$16:$A$35)*(A46<=$B$16:$B$35)*--((($C$16:$C$35="All dates")+($C$16:$C$35=B46))>0),{1;2;4;8;16;32;64;128;256;512;1024;2048;4096;8192;16384;32768;65536;131072;262144;524288}),2))+16,0),breakRow,IFERROR(INT(LOG(SUMPRODUCT(($A$16:$A$35<>"")*($B$16:$B$35<>"")*(A46>=$A$16:$A$35)*(A46<=$B$16:$B$35)*--((($C$16:$C$35="All dates")+($C$16:$C$35=B46))>0)*($F$16:$F$35=FALSE)*($F$16:$F$35<>"")*--((($D$16:$D$35="Break")+($D$16:$D$35="Holiday"))>0),{1;2;4;8;16;32;64;128;256;512;1024;2048;4096;8192;16384;32768;65536;131072;262144;524288}),2))+16,0),baseStatus,IF(base=0,"",INDEX($F$16:$F$35,base-15)),singleRow,IFERROR(INT(LOG(SUMPRODUCT(($A$16:$A$35<>"")*($B$16:$B$35<>"")*(A46>=$A$16:$A$35)*(A46<=$B$16:$B$35)*--((($C$16:$C$35="All dates")+($C$16:$C$35=B46))>0)*($A$16:$A$35=$B$16:$B$35)*($F$16:$F$35=baseStatus),{1;2;4;8;16;32;64;128;256;512;1024;2048;4096;8192;16384;32768;65536;131072;262144;524288}),2))+16,0),IF(breakRow>0,breakRow,IF(singleRow>0,singleRow,base))) -> 0
A47: =A46+1 -> 46247 | B47: =TEXT(A47,"dddd") -> Thursday | C47: =IFERROR(INDEX($I$7:$I$13,MATCH(B47,$H$7:$H$13,0)),FALSE) -> TRUE | D47: =IF($Q47=0,"",INDEX($D$16:$D$35,$Q47-ROW($A$16)+1)) | E47: =IF($Q47=0,"",INDEX($E$16:$E$35,$Q47-ROW($A$16)+1)) | F47: =IF($Q47=0,"",INDEX($F$16:$F$35,$Q47-ROW($A$16)+1)) | G47: =IF($Q47=0,"",INDEX($G$16:$G$35,$Q47-ROW($A$16)+1)) | H47: =IF(F47="",C47,F47) -> TRUE | I47: =IF(H47,COUNTIF($H$44:H47,TRUE),"") -> 4 | J47: =IFERROR(__xludf.DUMMYFUNCTION("IF(O47,LET(w,IFERROR(MATCH(N47,UNIQUE(FILTER($N$44:$N$408,$O$44:$O$408=TRUE)),0),""""),IF(OR(w="""",w>$B$6),"""",w)),"""")"),1.0) -> 1 | K47: =IF(J47="","","Term "&MIN($B$7,ROUNDUP(J47/$B$8,0))) -> Term 1 | L47: =IF(J47="","",MOD(J47-1,$B$8)+1) -> 1 | M47: =IF(J47="",FALSE,AND($B$9="Yes",MOD(J47,$B$8)=0)) -> FALSE | N47: =A47-WEEKDAY(A47,2)+1 -> 46244 | O47: =SUMPRODUCT(($N$44:$N$408=N47)*(WEEKDAY($A$44:$A$408,2)<=5)*--($H$44:$H$408=TRUE))>0 -> TRUE | Q47: =LET(base,IFERROR(INT(LOG(SUMPRODUCT(($A$16:$A$35<>"")*($B$16:$B$35<>"")*(A47>=$A$16:$A$35)*(A47<=$B$16:$B$35)*--((($C$16:$C$35="All dates")+($C$16:$C$35=B47))>0),{1;2;4;8;16;32;64;128;256;512;1024;2048;4096;8192;16384;32768;65536;131072;262144;524288}),2))+16,0),breakRow,IFERROR(INT(LOG(SUMPRODUCT(($A$16:$A$35<>"")*($B$16:$B$35<>"")*(A47>=$A$16:$A$35)*(A47<=$B$16:$B$35)*--((($C$16:$C$35="All dates")+($C$16:$C$35=B47))>0)*($F$16:$F$35=FALSE)*($F$16:$F$35<>"")*--((($D$16:$D$35="Break")+($D$16:$D$35="Holiday"))>0),{1;2;4;8;16;32;64;128;256;512;1024;2048;4096;8192;16384;32768;65536;131072;262144;524288}),2))+16,0),baseStatus,IF(base=0,"",INDEX($F$16:$F$35,base-15)),singleRow,IFERROR(INT(LOG(SUMPRODUCT(($A$16:$A$35<>"")*($B$16:$B$35<>"")*(A47>=$A$16:$A$35)*(A47<=$B$16:$B$35)*--((($C$16:$C$35="All dates")+($C$16:$C$35=B47))>0)*($A$16:$A$35=$B$16:$B$35)*($F$16:$F$35=baseStatus),{1;2;4;8;16;32;64;128;256;512;1024;2048;4096;8192;16384;32768;65536;131072;262144;524288}),2))+16,0),IF(breakRow>0,breakRow,IF(singleRow>0,singleRow,base))) -> 0
A48: =A47+1 -> 46248 | B48: =TEXT(A48,"dddd") -> Friday | C48: =IFERROR(INDEX($I$7:$I$13,MATCH(B48,$H$7:$H$13,0)),FALSE) -> TRUE | D48: =IF($Q48=0,"",INDEX($D$16:$D$35,$Q48-ROW($A$16)+1)) | E48: =IF($Q48=0,"",INDEX($E$16:$E$35,$Q48-ROW($A$16)+1)) | F48: =IF($Q48=0,"",INDEX($F$16:$F$35,$Q48-ROW($A$16)+1)) | G48: =IF($Q48=0,"",INDEX($G$16:$G$35,$Q48-ROW($A$16)+1)) | H48: =IF(F48="",C48,F48) -> TRUE | I48: =IF(H48,COUNTIF($H$44:H48,TRUE),"") -> 5 | J48: =IFERROR(__xludf.DUMMYFUNCTION("IF(O48,LET(w,IFERROR(MATCH(N48,UNIQUE(FILTER($N$44:$N$408,$O$44:$O$408=TRUE)),0),""""),IF(OR(w="""",w>$B$6),"""",w)),"""")"),1.0) -> 1 | K48: =IF(J48="","","Term "&MIN($B$7,ROUNDUP(J48/$B$8,0))) -> Term 1 | L48: =IF(J48="","",MOD(J48-1,$B$8)+1) -> 1 | M48: =IF(J48="",FALSE,AND($B$9="Yes",MOD(J48,$B$8)=0)) -> FALSE | N48: =A48-WEEKDAY(A48,2)+1 -> 46244 | O48: =SUMPRODUCT(($N$44:$N$408=N48)*(WEEKDAY($A$44:$A$408,2)<=5)*--($H$44:$H$408=TRUE))>0 -> TRUE | Q48: =LET(base,IFERROR(INT(LOG(SUMPRODUCT(($A$16:$A$35<>"")*($B$16:$B$35<>"")*(A48>=$A$16:$A$35)*(A48<=$B$16:$B$35)*--((($C$16:$C$35="All dates")+($C$16:$C$35=B48))>0),{1;2;4;8;16;32;64;128;256;512;1024;2048;4096;8192;16384;32768;65536;131072;262144;524288}),2))+16,0),breakRow,IFERROR(INT(LOG(SUMPRODUCT(($A$16:$A$35<>"")*($B$16:$B$35<>"")*(A48>=$A$16:$A$35)*(A48<=$B$16:$B$35)*--((($C$16:$C$35="All dates")+($C$16:$C$35=B48))>0)*($F$16:$F$35=FALSE)*($F$16:$F$35<>"")*--((($D$16:$D$35="Break")+($D$16:$D$35="Holiday"))>0),{1;2;4;8;16;32;64;128;256;512;1024;2048;4096;8192;16384;32768;65536;131072;262144;524288}),2))+16,0),baseStatus,IF(base=0,"",INDEX($F$16:$F$35,base-15)),singleRow,IFERROR(INT(LOG(SUMPRODUCT(($A$16:$A$35<>"")*($B$16:$B$35<>"")*(A48>=$A$16:$A$35)*(A48<=$B$16:$B$35)*--((($C$16:$C$35="All dates")+($C$16:$C$35=B48))>0)*($A$16:$A$35=$B$16:$B$35)*($F$16:$F$35=baseStatus),{1;2;4;8;16;32;64;128;256;512;1024;2048;4096;8192;16384;32768;65536;131072;262144;524288}),2))+16,0),IF(breakRow>0,breakRow,IF(singleRow>0,singleRow,base))) -> 0
A49: =A48+1 -> 46249 | B49: =TEXT(A49,"dddd") -> Saturday | C49: =IFERROR(INDEX($I$7:$I$13,MATCH(B49,$H$7:$H$13,0)),FALSE) -> FALSE | D49: =IF($Q49=0,"",INDEX($D$16:$D$35,$Q49-ROW($A$16)+1)) | E49: =IF($Q49=0,"",INDEX($E$16:$E$35,$Q49-ROW($A$16)+1)) | F49: =IF($Q49=0,"",INDEX($F$16:$F$35,$Q49-ROW($A$16)+1)) | G49: =IF($Q49=0,"",INDEX($G$16:$G$35,$Q49-ROW($A$16)+1)) | H49: =IF(F49="",C49,F49) -> FALSE | I49: =IF(H49,COUNTIF($H$44:H49,TRUE),"") | J49: =IFERROR(__xludf.DUMMYFUNCTION("IF(O49,LET(w,IFERROR(MATCH(N49,UNIQUE(FILTER($N$44:$N$408,$O$44:$O$408=TRUE)),0),""""),IF(OR(w="""",w>$B$6),"""",w)),"""")"),1.0) -> 1 | K49: =IF(J49="","","Term "&MIN($B$7,ROUNDUP(J49/$B$8,0))) -> Term 1 | L49: =IF(J49="","",MOD(J49-1,$B$8)+1) -> 1 | M49: =IF(J49="",FALSE,AND($B$9="Yes",MOD(J49,$B$8)=0)) -> FALSE | N49: =A49-WEEKDAY(A49,2)+1 -> 46244 | O49: =SUMPRODUCT(($N$44:$N$408=N49)*(WEEKDAY($A$44:$A$408,2)<=5)*--($H$44:$H$408=TRUE))>0 -> TRUE | Q49: =LET(base,IFERROR(INT(LOG(SUMPRODUCT(($A$16:$A$35<>"")*($B$16:$B$35<>"")*(A49>=$A$16:$A$35)*(A49<=$B$16:$B$35)*--((($C$16:$C$35="All dates")+($C$16:$C$35=B49))>0),{1;2;4;8;16;32;64;128;256;512;1024;2048;4096;8192;16384;32768;65536;131072;262144;524288}),2))+16,0),breakRow,IFERROR(INT(LOG(SUMPRODUCT(($A$16:$A$35<>"")*($B$16:$B$35<>"")*(A49>=$A$16:$A$35)*(A49<=$B$16:$B$35)*--((($C$16:$C$35="All dates")+($C$16:$C$35=B49))>0)*($F$16:$F$35=FALSE)*($F$16:$F$35<>"")*--((($D$16:$D$35="Break")+($D$16:$D$35="Holiday"))>0),{1;2;4;8;16;32;64;128;256;512;1024;2048;4096;8192;16384;32768;65536;131072;262144;524288}),2))+16,0),baseStatus,IF(base=0,"",INDEX($F$16:$F$35,base-15)),singleRow,IFERROR(INT(LOG(SUMPRODUCT(($A$16:$A$35<>"")*($B$16:$B$35<>"")*(A49>=$A$16:$A$35)*(A49<=$B$16:$B$35)*--((($C$16:$C$35="All dates")+($C$16:$C$35=B49))>0)*($A$16:$A$35=$B$16:$B$35)*($F$16:$F$35=baseStatus),{1;2;4;8;16;32;64;128;256;512;1024;2048;4096;8192;16384;32768;65536;131072;262144;524288}),2))+16,0),IF(breakRow>0,breakRow,IF(singleRow>0,singleRow,base))) -> 0
A50: =A49+1 -> 46250 | B50: =TEXT(A50,"dddd") -> Sunday | C50: =IFERROR(INDEX($I$7:$I$13,MATCH(B50,$H$7:$H$13,0)),FALSE) -> FALSE | D50: =IF($Q50=0,"",INDEX($D$16:$D$35,$Q50-ROW($A$16)+1)) | E50: =IF($Q50=0,"",INDEX($E$16:$E$35,$Q50-ROW($A$16)+1)) | F50: =IF($Q50=0,"",INDEX($F$16:$F$35,$Q50-ROW($A$16)+1)) | G50: =IF($Q50=0,"",INDEX($G$16:$G$35,$Q50-ROW($A$16)+1)) | H50: =IF(F50="",C50,F50) -> FALSE | I50: =IF(H50,COUNTIF($H$44:H50,TRUE),"") | J50: =IFERROR(__xludf.DUMMYFUNCTION("IF(O50,LET(w,IFERROR(MATCH(N50,UNIQUE(FILTER($N$44:$N$408,$O$44:$O$408=TRUE)),0),""""),IF(OR(w="""",w>$B$6),"""",w)),"""")"),1.0) -> 1 | K50: =IF(J50="","","Term "&MIN($B$7,ROUNDUP(J50/$B$8,0))) -> Term 1 | L50: =IF(J50="","",MOD(J50-1,$B$8)+1) -> 1 | M50: =IF(J50="",FALSE,AND($B$9="Yes",MOD(J50,$B$8)=0)) -> FALSE | N50: =A50-WEEKDAY(A50,2)+1 -> 46244 | O50: =SUMPRODUCT(($N$44:$N$408=N50)*(WEEKDAY($A$44:$A$408,2)<=5)*--($H$44:$H$408=TRUE))>0 -> TRUE | Q50: =LET(base,IFERROR(INT(LOG(SUMPRODUCT(($A$16:$A$35<>"")*($B$16:$B$35<>"")*(A50>=$A$16:$A$35)*(A50<=$B$16:$B$35)*--((($C$16:$C$35="All dates")+($C$16:$C$35=B50))>0),{1;2;4;8;16;32;64;128;256;512;1024;2048;4096;8192;16384;32768;65536;131072;262144;524288}),2))+16,0),breakRow,IFERROR(INT(LOG(SUMPRODUCT(($A$16:$A$35<>"")*($B$16:$B$35<>"")*(A50>=$A$16:$A$35)*(A50<=$B$16:$B$35)*--((($C$16:$C$35="All dates")+($C$16:$C$35=B50))>0)*($F$16:$F$35=FALSE)*($F$16:$F$35<>"")*--((($D$16:$D$35="Break")+($D$16:$D$35="Holiday"))>0),{1;2;4;8;16;32;64;128;256;512;1024;2048;4096;8192;16384;32768;65536;131072;262144;524288}),2))+16,0),baseStatus,IF(base=0,"",INDEX($F$16:$F$35,base-15)),singleRow,IFERROR(INT(LOG(SUMPRODUCT(($A$16:$A$35<>"")*($B$16:$B$35<>"")*(A50>=$A$16:$A$35)*(A50<=$B$16:$B$35)*--((($C$16:$C$35="All dates")+($C$16:$C$35=B50))>0)*($A$16:$A$35=$B$16:$B$35)*($F$16:$F$35=baseStatus),{1;2;4;8;16;32;64;128;256;512;1024;2048;4096;8192;16384;32768;65536;131072;262144;524288}),2))+16,0),IF(breakRow>0,breakRow,IF(singleRow>0,singleRow,base))) -> 0
A51: =A50+1 -> 46251 | B51: =TEXT(A51,"dddd") -> Monday | C51: =IFERROR(INDEX($I$7:$I$13,MATCH(B51,$H$7:$H$13,0)),FALSE) -> TRUE | D51: =IF($Q51=0,"",INDEX($D$16:$D$35,$Q51-ROW($A$16)+1)) | E51: =IF($Q51=0,"",INDEX($E$16:$E$35,$Q51-ROW($A$16)+1)) | F51: =IF($Q51=0,"",INDEX($F$16:$F$35,$Q51-ROW($A$16)+1)) | G51: =IF($Q51=0,"",INDEX($G$16:$G$35,$Q51-ROW($A$16)+1)) | H51: =IF(F51="",C51,F51) -> TRUE | I51: =IF(H51,COUNTIF($H$44:H51,TRUE),"") -> 6 | J51: =IFERROR(__xludf.DUMMYFUNCTION("IF(O51,LET(w,IFERROR(MATCH(N51,UNIQUE(FILTER($N$44:$N$408,$O$44:$O$408=TRUE)),0),""""),IF(OR(w="""",w>$B$6),"""",w)),"""")"),2.0) -> 2 | K51: =IF(J51="","","Term "&MIN($B$7,ROUNDUP(J51/$B$8,0))) -> Term 1 | L51: =IF(J51="","",MOD(J51-1,$B$8)+1) -> 2 | M51: =IF(J51="",FALSE,AND($B$9="Yes",MOD(J51,$B$8)=0)) -> FALSE | N51: =A51-WEEKDAY(A51,2)+1 -> 46251 | O51: =SUMPRODUCT(($N$44:$N$408=N51)*(WEEKDAY($A$44:$A$408,2)<=5)*--($H$44:$H$408=TRUE))>0 -> TRUE | Q51: =LET(base,IFERROR(INT(LOG(SUMPRODUCT(($A$16:$A$35<>"")*($B$16:$B$35<>"")*(A51>=$A$16:$A$35)*(A51<=$B$16:$B$35)*--((($C$16:$C$35="All dates")+($C$16:$C$35=B51))>0),{1;2;4;8;16;32;64;128;256;512;1024;2048;4096;8192;16384;32768;65536;131072;262144;524288}),2))+16,0),breakRow,IFERROR(INT(LOG(SUMPRODUCT(($A$16:$A$35<>"")*($B$16:$B$35<>"")*(A51>=$A$16:$A$35)*(A51<=$B$16:$B$35)*--((($C$16:$C$35="All dates")+($C$16:$C$35=B51))>0)*($F$16:$F$35=FALSE)*($F$16:$F$35<>"")*--((($D$16:$D$35="Break")+($D$16:$D$35="Holiday"))>0),{1;2;4;8;16;32;64;128;256;512;1024;2048;4096;8192;16384;32768;65536;131072;262144;524288}),2))+16,0),baseStatus,IF(base=0,"",INDEX($F$16:$F$35,base-15)),singleRow,IFERROR(INT(LOG(SUMPRODUCT(($A$16:$A$35<>"")*($B$16:$B$35<>"")*(A51>=$A$16:$A$35)*(A51<=$B$16:$B$35)*--((($C$16:$C$35="All dates")+($C$16:$C$35=B51))>0)*($A$16:$A$35=$B$16:$B$35)*($F$16:$F$35=baseStatus),{1;2;4;8;16;32;64;128;256;512;1024;2048;4096;8192;16384;32768;65536;131072;262144;524288}),2))+16,0),IF(breakRow>0,breakRow,IF(singleRow>0,singleRow,base))) -> 0
A52: =A51+1 -> 46252 | B52: =TEXT(A52,"dddd") -> Tuesday | C52: =IFERROR(INDEX($I$7:$I$13,MATCH(B52,$H$7:$H$13,0)),FALSE) -> TRUE | D52: =IF($Q52=0,"",INDEX($D$16:$D$35,$Q52-ROW($A$16)+1)) | E52: =IF($Q52=0,"",INDEX($E$16:$E$35,$Q52-ROW($A$16)+1)) | F52: =IF($Q52=0,"",INDEX($F$16:$F$35,$Q52-ROW($A$16)+1)) | G52: =IF($Q52=0,"",INDEX($G$16:$G$35,$Q52-ROW($A$16)+1)) | H52: =IF(F52="",C52,F52) -> TRUE | I52: =IF(H52,COUNTIF($H$44:H52,TRUE),"") -> 7 | J52: =IFERROR(__xludf.DUMMYFUNCTION("IF(O52,LET(w,IFERROR(MATCH(N52,UNIQUE(FILTER($N$44:$N$408,$O$44:$O$408=TRUE)),0),""""),IF(OR(w="""",w>$B$6),"""",w)),"""")"),2.0) -> 2 | K52: =IF(J52="","","Term "&MIN($B$7,ROUNDUP(J52/$B$8,0))) -> Term 1 | L52: =IF(J52="","",MOD(J52-1,$B$8)+1) -> 2 | M52: =IF(J52="",FALSE,AND($B$9="Yes",MOD(J52,$B$8)=0)) -> FALSE | N52: =A52-WEEKDAY(A52,2)+1 -> 46251 | O52: =SUMPRODUCT(($N$44:$N$408=N52)*(WEEKDAY($A$44:$A$408,2)<=5)*--($H$44:$H$408=TRUE))>0 -> TRUE | Q52: =LET(base,IFERROR(INT(LOG(SUMPRODUCT(($A$16:$A$35<>"")*($B$16:$B$35<>"")*(A52>=$A$16:$A$35)*(A52<=$B$16:$B$35)*--((($C$16:$C$35="All dates")+($C$16:$C$35=B52))>0),{1;2;4;8;16;32;64;128;256;512;1024;2048;4096;8192;16384;32768;65536;131072;262144;524288}),2))+16,0),breakRow,IFERROR(INT(LOG(SUMPRODUCT(($A$16:$A$35<>"")*($B$16:$B$35<>"")*(A52>=$A$16:$A$35)*(A52<=$B$16:$B$35)*--((($C$16:$C$35="All dates")+($C$16:$C$35=B52))>0)*($F$16:$F$35=FALSE)*($F$16:$F$35<>"")*--((($D$16:$D$35="Break")+($D$16:$D$35="Holiday"))>0),{1;2;4;8;16;32;64;128;256;512;1024;2048;4096;8192;16384;32768;65536;131072;262144;524288}),2))+16,0),baseStatus,IF(base=0,"",INDEX($F$16:$F$35,base-15)),singleRow,IFERROR(INT(LOG(SUMPRODUCT(($A$16:$A$35<>"")*($B$16:$B$35<>"")*(A52>=$A$16:$A$35)*(A52<=$B$16:$B$35)*--((($C$16:$C$35="All dates")+($C$16:$C$35=B52))>0)*($A$16:$A$35=$B$16:$B$35)*($F$16:$F$35=baseStatus),{1;2;4;8;16;32;64;128;256;512;1024;2048;4096;8192;16384;32768;65536;131072;262144;524288}),2))+16,0),IF(breakRow>0,breakRow,IF(singleRow>0,singleRow,base))) -> 0
...

Sheet Family Map
A1: Family Map
A2: Step 3 • Review the feast and customize strands only when needed. Finalize strand names before placing strands or adding resources. Done when the active strands reflect this year’s plan. Next: Strand Placement.
A4: Form / Stage | B4: Bible | C4: Language Arts | D4: Literature | E4: History | F4: Geography | G4: Citizenship | H4: Science / Nature | I4: Math | J4: Beauty + Hands | K4: Foreign Language
A5: All Together | B5: =IFERROR(__xludf.DUMMYFUNCTION("IFERROR(INDEX(FILTER($D$46:$D$147,((($A$46:$A$147=TRUE)+($A$46:$A$147=""☑"")+($A$46:$A$147=""✓"")+($A$46:$A$147=""✔""))>0)*($B$46:$B$147=$A$5)*($C$46:$C$147=B$4)),ROWS(B$5:B5)),"""")"),"New Testament") -> New Testament | C5: =IFERROR(__xludf.DUMMYFUNCTION("IFERROR(INDEX(FILTER($D$46:$D$147,((($A$46:$A$147=TRUE)+($A$46:$A$147=""☑"")+($A$46:$A$147=""✓"")+($A$46:$A$147=""✔""))>0)*($B$46:$B$147=$A$5)*($C$46:$C$147=C$4)),ROWS(C$5:C5)),"""")"),"") | D5: =IFERROR(__xludf.DUMMYFUNCTION("IFERROR(INDEX(FILTER($D$46:$D$147,((($A$46:$A$147=TRUE)+($A$46:$A$147=""☑"")+($A$46:$A$147=""✓"")+($A$46:$A$147=""✔""))>0)*($B$46:$B$147=$A$5)*($C$46:$C$147=D$4)),ROWS(D$5:D5)),"""")"),"Family Read-Aloud") -> Family Read-Aloud | E5: =IFERROR(__xludf.DUMMYFUNCTION("IFERROR(INDEX(FILTER($D$46:$D$147,((($A$46:$A$147=TRUE)+($A$46:$A$147=""☑"")+($A$46:$A$147=""✓"")+($A$46:$A$147=""✔""))>0)*($B$46:$B$147=$A$5)*($C$46:$C$147=E$4)),ROWS(E$5:E5)),"""")"),"") | F5: =IFERROR(__xludf.DUMMYFUNCTION("IFERROR(INDEX(FILTER($D$46:$D$147,((($A$46:$A$147=TRUE)+($A$46:$A$147=""☑"")+($A$46:$A$147=""✓"")+($A$46:$A$147=""✔""))>0)*($B$46:$B$147=$A$5)*($C$46:$C$147=F$4)),ROWS(F$5:F5)),"""")"),"") | G5: =IFERROR(__xludf.DUMMYFUNCTION("IFERROR(INDEX(FILTER($D$46:$D$147,((($A$46:$A$147=TRUE)+($A$46:$A$147=""☑"")+($A$46:$A$147=""✓"")+($A$46:$A$147=""✔""))>0)*($B$46:$B$147=$A$5)*($C$46:$C$147=G$4)),ROWS(G$5:G5)),"""")"),"") | H5: =IFERROR(__xludf.DUMMYFUNCTION("IFERROR(INDEX(FILTER($D$46:$D$147,((($A$46:$A$147=TRUE)+($A$46:$A$147=""☑"")+($A$46:$A$147=""✓"")+($A$46:$A$147=""✔""))>0)*($B$46:$B$147=$A$5)*($C$46:$C$147=H$4)),ROWS(H$5:H5)),"""")"),"Special Studies") -> Special Studies | I5: =IFERROR(__xludf.DUMMYFUNCTION("IFERROR(INDEX(FILTER($D$46:$D$147,((($A$46:$A$147=TRUE)+($A$46:$A$147=""☑"")+($A$46:$A$147=""✓"")+($A$46:$A$147=""✔""))>0)*($B$46:$B$147=$A$5)*($C$46:$C$147=I$4)),ROWS(I$5:I5)),"""")"),"Family Math") -> Family Math | J5: =IFERROR(__xludf.DUMMYFUNCTION("IFERROR(INDEX(FILTER($D$46:$D$147,((($A$46:$A$147=TRUE)+($A$46:$A$147=""☑"")+($A$46:$A$147=""✓"")+($A$46:$A$147=""✔""))>0)*($B$46:$B$147=$A$5)*($C$46:$C$147=J$4)),ROWS(J$5:J5)),"""")"),"Hymn") -> Hymn | K5: =IFERROR(__xludf.DUMMYFUNCTION("IFERROR(INDEX(FILTER($D$46:$D$147,((($A$46:$A$147=TRUE)+($A$46:$A$147=""☑"")+($A$46:$A$147=""✓"")+($A$46:$A$147=""✔""))>0)*($B$46:$B$147=$A$5)*($C$46:$C$147=K$4)),ROWS(K$5:K5)),"""")"),"Family Language Song") -> Family Language Song
B6: =IFERROR(__xludf.DUMMYFUNCTION("IFERROR(INDEX(FILTER($D$46:$D$147,((($A$46:$A$147=TRUE)+($A$46:$A$147=""☑"")+($A$46:$A$147=""✓"")+($A$46:$A$147=""✔""))>0)*($B$46:$B$147=$A$5)*($C$46:$C$147=B$4)),ROWS(B$5:B6)),"""")"),"Old Testament") -> Old Testament | C6: =IFERROR(__xludf.DUMMYFUNCTION("IFERROR(INDEX(FILTER($D$46:$D$147,((($A$46:$A$147=TRUE)+($A$46:$A$147=""☑"")+($A$46:$A$147=""✓"")+($A$46:$A$147=""✔""))>0)*($B$46:$B$147=$A$5)*($C$46:$C$147=C$4)),ROWS(C$5:C6)),"""")"),"") | D6: =IFERROR(__xludf.DUMMYFUNCTION("IFERROR(INDEX(FILTER($D$46:$D$147,((($A$46:$A$147=TRUE)+($A$46:$A$147=""☑"")+($A$46:$A$147=""✓"")+($A$46:$A$147=""✔""))>0)*($B$46:$B$147=$A$5)*($C$46:$C$147=D$4)),ROWS(D$5:D6)),"""")"),"Tales / Fairy Tales / Myths") -> Tales / Fairy Tales / Myths | E6: =IFERROR(__xludf.DUMMYFUNCTION("IFERROR(INDEX(FILTER($D$46:$D$147,((($A$46:$A$147=TRUE)+($A$46:$A$147=""☑"")+($A$46:$A$147=""✓"")+($A$46:$A$147=""✔""))>0)*($B$46:$B$147=$A$5)*($C$46:$C$147=E$4)),ROWS(E$5:E6)),"""")"),"") | F6: =IFERROR(__xludf.DUMMYFUNCTION("IFERROR(INDEX(FILTER($D$46:$D$147,((($A$46:$A$147=TRUE)+($A$46:$A$147=""☑"")+($A$46:$A$147=""✓"")+($A$46:$A$147=""✔""))>0)*($B$46:$B$147=$A$5)*($C$46:$C$147=F$4)),ROWS(F$5:F6)),"""")"),"") | G6: =IFERROR(__xludf.DUMMYFUNCTION("IFERROR(INDEX(FILTER($D$46:$D$147,((($A$46:$A$147=TRUE)+($A$46:$A$147=""☑"")+($A$46:$A$147=""✓"")+($A$46:$A$147=""✔""))>0)*($B$46:$B$147=$A$5)*($C$46:$C$147=G$4)),ROWS(G$5:G6)),"""")"),"") | H6: =IFERROR(__xludf.DUMMYFUNCTION("IFERROR(INDEX(FILTER($D$46:$D$147,((($A$46:$A$147=TRUE)+($A$46:$A$147=""☑"")+($A$46:$A$147=""✓"")+($A$46:$A$147=""✔""))>0)*($B$46:$B$147=$A$5)*($C$46:$C$147=H$4)),ROWS(H$5:H6)),"""")"),"") | I6: =IFERROR(__xludf.DUMMYFUNCTION("IFERROR(INDEX(FILTER($D$46:$D$147,((($A$46:$A$147=TRUE)+($A$46:$A$147=""☑"")+($A$46:$A$147=""✓"")+($A$46:$A$147=""✔""))>0)*($B$46:$B$147=$A$5)*($C$46:$C$147=I$4)),ROWS(I$5:I6)),"""")"),"") | J6: =IFERROR(__xludf.DUMMYFUNCTION("IFERROR(INDEX(FILTER($D$46:$D$147,((($A$46:$A$147=TRUE)+($A$46:$A$147=""☑"")+($A$46:$A$147=""✓"")+($A$46:$A$147=""✔""))>0)*($B$46:$B$147=$A$5)*($C$46:$C$147=J$4)),ROWS(J$5:J6)),"""")"),"Folk Song") -> Folk Song | K6: =IFERROR(__xludf.DUMMYFUNCTION("IFERROR(INDEX(FILTER($D$46:$D$147,((($A$46:$A$147=TRUE)+($A$46:$A$147=""☑"")+($A$46:$A$147=""✓"")+($A$46:$A$147=""✔""))>0)*($B$46:$B$147=$A$5)*($C$46:$C$147=K$4)),ROWS(K$5:K6)),"""")"),"")
B7: =IFERROR(__xludf.DUMMYFUNCTION("IFERROR(INDEX(FILTER($D$46:$D$147,((($A$46:$A$147=TRUE)+($A$46:$A$147=""☑"")+($A$46:$A$147=""✓"")+($A$46:$A$147=""✔""))>0)*($B$46:$B$147=$A$5)*($C$46:$C$147=B$4)),ROWS(B$5:B7)),"""")"),"Psalms / Proverbs") -> Psalms / Proverbs | C7: =IFERROR(__xludf.DUMMYFUNCTION("IFERROR(INDEX(FILTER($D$46:$D$147,((($A$46:$A$147=TRUE)+($A$46:$A$147=""☑"")+($A$46:$A$147=""✓"")+($A$46:$A$147=""✔""))>0)*($B$46:$B$147=$A$5)*($C$46:$C$147=C$4)),ROWS(C$5:C7)),"""")"),"") | D7: =IFERROR(__xludf.DUMMYFUNCTION("IFERROR(INDEX(FILTER($D$46:$D$147,((($A$46:$A$147=TRUE)+($A$46:$A$147=""☑"")+($A$46:$A$147=""✓"")+($A$46:$A$147=""✔""))>0)*($B$46:$B$147=$A$5)*($C$46:$C$147=D$4)),ROWS(D$5:D7)),"""")"),"") | E7: =IFERROR(__xludf.DUMMYFUNCTION("IFERROR(INDEX(FILTER($D$46:$D$147,((($A$46:$A$147=TRUE)+($A$46:$A$147=""☑"")+($A$46:$A$147=""✓"")+($A$46:$A$147=""✔""))>0)*($B$46:$B$147=$A$5)*($C$46:$C$147=E$4)),ROWS(E$5:E7)),"""")"),"") | F7: =IFERROR(__xludf.DUMMYFUNCTION("IFERROR(INDEX(FILTER($D$46:$D$147,((($A$46:$A$147=TRUE)+($A$46:$A$147=""☑"")+($A$46:$A$147=""✓"")+($A$46:$A$147=""✔""))>0)*($B$46:$B$147=$A$5)*($C$46:$C$147=F$4)),ROWS(F$5:F7)),"""")"),"") | G7: =IFERROR(__xludf.DUMMYFUNCTION("IFERROR(INDEX(FILTER($D$46:$D$147,((($A$46:$A$147=TRUE)+($A$46:$A$147=""☑"")+($A$46:$A$147=""✓"")+($A$46:$A$147=""✔""))>0)*($B$46:$B$147=$A$5)*($C$46:$C$147=G$4)),ROWS(G$5:G7)),"""")"),"") | H7: =IFERROR(__xludf.DUMMYFUNCTION("IFERROR(INDEX(FILTER($D$46:$D$147,((($A$46:$A$147=TRUE)+($A$46:$A$147=""☑"")+($A$46:$A$147=""✓"")+($A$46:$A$147=""✔""))>0)*($B$46:$B$147=$A$5)*($C$46:$C$147=H$4)),ROWS(H$5:H7)),"""")"),"") | I7: =IFERROR(__xludf.DUMMYFUNCTION("IFERROR(INDEX(FILTER($D$46:$D$147,((($A$46:$A$147=TRUE)+($A$46:$A$147=""☑"")+($A$46:$A$147=""✓"")+($A$46:$A$147=""✔""))>0)*($B$46:$B$147=$A$5)*($C$46:$C$147=I$4)),ROWS(I$5:I7)),"""")"),"") | J7: =IFERROR(__xludf.DUMMYFUNCTION("IFERROR(INDEX(FILTER($D$46:$D$147,((($A$46:$A$147=TRUE)+($A$46:$A$147=""☑"")+($A$46:$A$147=""✓"")+($A$46:$A$147=""✔""))>0)*($B$46:$B$147=$A$5)*($C$46:$C$147=J$4)),ROWS(J$5:J7)),"""")"),"Poetry") -> Poetry | K7: =IFERROR(__xludf.DUMMYFUNCTION("IFERROR(INDEX(FILTER($D$46:$D$147,((($A$46:$A$147=TRUE)+($A$46:$A$147=""☑"")+($A$46:$A$147=""✓"")+($A$46:$A$147=""✔""))>0)*($B$46:$B$147=$A$5)*($C$46:$C$147=K$4)),ROWS(K$5:K7)),"""")"),"")
B8: =IFERROR(__xludf.DUMMYFUNCTION("IFERROR(INDEX(FILTER($D$46:$D$147,((($A$46:$A$147=TRUE)+($A$46:$A$147=""☑"")+($A$46:$A$147=""✓"")+($A$46:$A$147=""✔""))>0)*($B$46:$B$147=$A$5)*($C$46:$C$147=B$4)),ROWS(B$5:B8)),"""")"),"Scripture Memory") -> Scripture Memory | C8: =IFERROR(__xludf.DUMMYFUNCTION("IFERROR(INDEX(FILTER($D$46:$D$147,((($A$46:$A$147=TRUE)+($A$46:$A$147=""☑"")+($A$46:$A$147=""✓"")+($A$46:$A$147=""✔""))>0)*($B$46:$B$147=$A$5)*($C$46:$C$147=C$4)),ROWS(C$5:C8)),"""")"),"") | D8: =IFERROR(__xludf.DUMMYFUNCTION("IFERROR(INDEX(FILTER($D$46:$D$147,((($A$46:$A$147=TRUE)+($A$46:$A$147=""☑"")+($A$46:$A$147=""✓"")+($A$46:$A$147=""✔""))>0)*($B$46:$B$147=$A$5)*($C$46:$C$147=D$4)),ROWS(D$5:D8)),"""")"),"") | E8: =IFERROR(__xludf.DUMMYFUNCTION("IFERROR(INDEX(FILTER($D$46:$D$147,((($A$46:$A$147=TRUE)+($A$46:$A$147=""☑"")+($A$46:$A$147=""✓"")+($A$46:$A$147=""✔""))>0)*($B$46:$B$147=$A$5)*($C$46:$C$147=E$4)),ROWS(E$5:E8)),"""")"),"") | F8: =IFERROR(__xludf.DUMMYFUNCTION("IFERROR(INDEX(FILTER($D$46:$D$147,((($A$46:$A$147=TRUE)+($A$46:$A$147=""☑"")+($A$46:$A$147=""✓"")+($A$46:$A$147=""✔""))>0)*($B$46:$B$147=$A$5)*($C$46:$C$147=F$4)),ROWS(F$5:F8)),"""")"),"") | G8: =IFERROR(__xludf.DUMMYFUNCTION("IFERROR(INDEX(FILTER($D$46:$D$147,((($A$46:$A$147=TRUE)+($A$46:$A$147=""☑"")+($A$46:$A$147=""✓"")+($A$46:$A$147=""✔""))>0)*($B$46:$B$147=$A$5)*($C$46:$C$147=G$4)),ROWS(G$5:G8)),"""")"),"") | H8: =IFERROR(__xludf.DUMMYFUNCTION("IFERROR(INDEX(FILTER($D$46:$D$147,((($A$46:$A$147=TRUE)+($A$46:$A$147=""☑"")+($A$46:$A$147=""✓"")+($A$46:$A$147=""✔""))>0)*($B$46:$B$147=$A$5)*($C$46:$C$147=H$4)),ROWS(H$5:H8)),"""")"),"") | I8: =IFERROR(__xludf.DUMMYFUNCTION("IFERROR(INDEX(FILTER($D$46:$D$147,((($A$46:$A$147=TRUE)+($A$46:$A$147=""☑"")+($A$46:$A$147=""✓"")+($A$46:$A$147=""✔""))>0)*($B$46:$B$147=$A$5)*($C$46:$C$147=I$4)),ROWS(I$5:I8)),"""")"),"") | J8: =IFERROR(__xludf.DUMMYFUNCTION("IFERROR(INDEX(FILTER($D$46:$D$147,((($A$46:$A$147=TRUE)+($A$46:$A$147=""☑"")+($A$46:$A$147=""✓"")+($A$46:$A$147=""✔""))>0)*($B$46:$B$147=$A$5)*($C$46:$C$147=J$4)),ROWS(J$5:J8)),"""")"),"Picture Study") -> Picture Study | K8: =IFERROR(__xludf.DUMMYFUNCTION("IFERROR(INDEX(FILTER($D$46:$D$147,((($A$46:$A$147=TRUE)+($A$46:$A$147=""☑"")+($A$46:$A$147=""✓"")+($A$46:$A$147=""✔""))>0)*($B$46:$B$147=$A$5)*($C$46:$C$147=K$4)),ROWS(K$5:K8)),"""")"),"")
B9: =IFERROR(__xludf.DUMMYFUNCTION("IFERROR(INDEX(FILTER($D$46:$D$147,((($A$46:$A$147=TRUE)+($A$46:$A$147=""☑"")+($A$46:$A$147=""✓"")+($A$46:$A$147=""✔""))>0)*($B$46:$B$147=$A$5)*($C$46:$C$147=B$4)),ROWS(B$5:B9)),"""")"),"") | C9: =IFERROR(__xludf.DUMMYFUNCTION("IFERROR(INDEX(FILTER($D$46:$D$147,((($A$46:$A$147=TRUE)+($A$46:$A$147=""☑"")+($A$46:$A$147=""✓"")+($A$46:$A$147=""✔""))>0)*($B$46:$B$147=$A$5)*($C$46:$C$147=C$4)),ROWS(C$5:C9)),"""")"),"") | D9: =IFERROR(__xludf.DUMMYFUNCTION("IFERROR(INDEX(FILTER($D$46:$D$147,((($A$46:$A$147=TRUE)+($A$46:$A$147=""☑"")+($A$46:$A$147=""✓"")+($A$46:$A$147=""✔""))>0)*($B$46:$B$147=$A$5)*($C$46:$C$147=D$4)),ROWS(D$5:D9)),"""")"),"") | E9: =IFERROR(__xludf.DUMMYFUNCTION("IFERROR(INDEX(FILTER($D$46:$D$147,((($A$46:$A$147=TRUE)+($A$46:$A$147=""☑"")+($A$46:$A$147=""✓"")+($A$46:$A$147=""✔""))>0)*($B$46:$B$147=$A$5)*($C$46:$C$147=E$4)),ROWS(E$5:E9)),"""")"),"") | F9: =IFERROR(__xludf.DUMMYFUNCTION("IFERROR(INDEX(FILTER($D$46:$D$147,((($A$46:$A$147=TRUE)+($A$46:$A$147=""☑"")+($A$46:$A$147=""✓"")+($A$46:$A$147=""✔""))>0)*($B$46:$B$147=$A$5)*($C$46:$C$147=F$4)),ROWS(F$5:F9)),"""")"),"") | G9: =IFERROR(__xludf.DUMMYFUNCTION("IFERROR(INDEX(FILTER($D$46:$D$147,((($A$46:$A$147=TRUE)+($A$46:$A$147=""☑"")+($A$46:$A$147=""✓"")+($A$46:$A$147=""✔""))>0)*($B$46:$B$147=$A$5)*($C$46:$C$147=G$4)),ROWS(G$5:G9)),"""")"),"") | H9: =IFERROR(__xludf.DUMMYFUNCTION("IFERROR(INDEX(FILTER($D$46:$D$147,((($A$46:$A$147=TRUE)+($A$46:$A$147=""☑"")+($A$46:$A$147=""✓"")+($A$46:$A$147=""✔""))>0)*($B$46:$B$147=$A$5)*($C$46:$C$147=H$4)),ROWS(H$5:H9)),"""")"),"") | I9: =IFERROR(__xludf.DUMMYFUNCTION("IFERROR(INDEX(FILTER($D$46:$D$147,((($A$46:$A$147=TRUE)+($A$46:$A$147=""☑"")+($A$46:$A$147=""✓"")+($A$46:$A$147=""✔""))>0)*($B$46:$B$147=$A$5)*($C$46:$C$147=I$4)),ROWS(I$5:I9)),"""")"),"") | J9: =IFERROR(__xludf.DUMMYFUNCTION("IFERROR(INDEX(FILTER($D$46:$D$147,((($A$46:$A$147=TRUE)+($A$46:$A$147=""☑"")+($A$46:$A$147=""✓"")+($A$46:$A$147=""✔""))>0)*($B$46:$B$147=$A$5)*($C$46:$C$147=J$4)),ROWS(J$5:J9)),"""")"),"Composer Study") -> Composer Study | K9: =IFERROR(__xludf.DUMMYFUNCTION("IFERROR(INDEX(FILTER($D$46:$D$147,((($A$46:$A$147=TRUE)+($A$46:$A$147=""☑"")+($A$46:$A$147=""✓"")+($A$46:$A$147=""✔""))>0)*($B$46:$B$147=$A$5)*($C$46:$C$147=K$4)),ROWS(K$5:K9)),"""")"),"")
A11: Form I | B11: =IFERROR(__xludf.DUMMYFUNCTION("IFERROR(INDEX(FILTER($D$46:$D$147,((($A$46:$A$147=TRUE)+($A$46:$A$147=""☑"")+($A$46:$A$147=""✓"")+($A$46:$A$147=""✔""))>0)*($B$46:$B$147=$A$11)*($C$46:$C$147=B$4)),ROWS(B$11:B11)),"""")"),"") | C11: =IFERROR(__xludf.DUMMYFUNCTION("IFERROR(INDEX(FILTER($D$46:$D$147,((($A$46:$A$147=TRUE)+($A$46:$A$147=""☑"")+($A$46:$A$147=""✓"")+($A$46:$A$147=""✔""))>0)*($B$46:$B$147=$A$11)*($C$46:$C$147=C$4)),ROWS(C$11:C11)),"""")"),"Reading Practice / Phonics") -> Reading Practice / Phonics | D11: =IFERROR(__xludf.DUMMYFUNCTION("IFERROR(INDEX(FILTER($D$46:$D$147,((($A$46:$A$147=TRUE)+($A$46:$A$147=""☑"")+($A$46:$A$147=""✓"")+($A$46:$A$147=""✔""))>0)*($B$46:$B$147=$A$11)*($C$46:$C$147=D$4)),ROWS(D$11:D11)),"""")"),"Reader / Phonics") -> Reader / Phonics | E11: =IFERROR(__xludf.DUMMYFUNCTION("IFERROR(INDEX(FILTER($D$46:$D$147,((($A$46:$A$147=TRUE)+($A$46:$A$147=""☑"")+($A$46:$A$147=""✓"")+($A$46:$A$147=""✔""))>0)*($B$46:$B$147=$A$11)*($C$46:$C$147=E$4)),ROWS(E$11:E11)),"""")"),"Picture Books") -> Picture Books | F11: =IFERROR(__xludf.DUMMYFUNCTION("IFERROR(INDEX(FILTER($D$46:$D$147,((($A$46:$A$147=TRUE)+($A$46:$A$147=""☑"")+($A$46:$A$147=""✓"")+($A$46:$A$147=""✔""))>0)*($B$46:$B$147=$A$11)*($C$46:$C$147=F$4)),ROWS(F$11:F11)),"""")"),"Map / Place Stories") -> Map / Place Stories | G11: =IFERROR(__xludf.DUMMYFUNCTION("IFERROR(INDEX(FILTER($D$46:$D$147,((($A$46:$A$147=TRUE)+($A$46:$A$147=""☑"")+($A$46:$A$147=""✓"")+($A$46:$A$147=""✔""))>0)*($B$46:$B$147=$A$11)*($C$46:$C$147=G$4)),ROWS(G$11:G11)),"""")"),"") | H11: =IFERROR(__xludf.DUMMYFUNCTION("IFERROR(INDEX(FILTER($D$46:$D$147,((($A$46:$A$147=TRUE)+($A$46:$A$147=""☑"")+($A$46:$A$147=""✓"")+($A$46:$A$147=""✔""))>0)*($B$46:$B$147=$A$11)*($C$46:$C$147=H$4)),ROWS(H$11:H11)),"""")"),"") | I11: =IFERROR(__xludf.DUMMYFUNCTION("IFERROR(INDEX(FILTER($D$46:$D$147,((($A$46:$A$147=TRUE)+($A$46:$A$147=""☑"")+($A$46:$A$147=""✓"")+($A$46:$A$147=""✔""))>0)*($B$46:$B$147=$A$11)*($C$46:$C$147=I$4)),ROWS(I$11:I11)),"""")"),"Math") -> Math | J11: =IFERROR(__xludf.DUMMYFUNCTION("IFERROR(INDEX(FILTER($D$46:$D$147,((($A$46:$A$147=TRUE)+($A$46:$A$147=""☑"")+($A$46:$A$147=""✓"")+($A$46:$A$147=""✔""))>0)*($B$46:$B$147=$A$11)*($C$46:$C$147=J$4)),ROWS(J$11:J11)),"""")"),"Drawing / Brush Drawing") -> Drawing / Brush Drawing | K11: =IFERROR(__xludf.DUMMYFUNCTION("IFERROR(INDEX(FILTER($D$46:$D$147,((($A$46:$A$147=TRUE)+($A$46:$A$147=""☑"")+($A$46:$A$147=""✓"")+($A$46:$A$147=""✔""))>0)*($B$46:$B$147=$A$11)*($C$46:$C$147=K$4)),ROWS(K$11:K11)),"""")"),"")
B12: =IFERROR(__xludf.DUMMYFUNCTION("IFERROR(INDEX(FILTER($D$46:$D$147,((($A$46:$A$147=TRUE)+($A$46:$A$147=""☑"")+($A$46:$A$147=""✓"")+($A$46:$A$147=""✔""))>0)*($B$46:$B$147=$A$11)*($C$46:$C$147=B$4)),ROWS(B$11:B12)),"""")"),"") | C12: =IFERROR(__xludf.DUMMYFUNCTION("IFERROR(INDEX(FILTER($D$46:$D$147,((($A$46:$A$147=TRUE)+($A$46:$A$147=""☑"")+($A$46:$A$147=""✓"")+($A$46:$A$147=""✔""))>0)*($B$46:$B$147=$A$11)*($C$46:$C$147=C$4)),ROWS(C$11:C12)),"""")"),"Copywork") -> Copywork | D12: =IFERROR(__xludf.DUMMYFUNCTION("IFERROR(INDEX(FILTER($D$46:$D$147,((($A$46:$A$147=TRUE)+($A$46:$A$147=""☑"")+($A$46:$A$147=""✓"")+($A$46:$A$147=""✔""))>0)*($B$46:$B$147=$A$11)*($C$46:$C$147=D$4)),ROWS(D$11:D12)),"""")"),"") | E12: =IFERROR(__xludf.DUMMYFUNCTION("IFERROR(INDEX(FILTER($D$46:$D$147,((($A$46:$A$147=TRUE)+($A$46:$A$147=""☑"")+($A$46:$A$147=""✓"")+($A$46:$A$147=""✔""))>0)*($B$46:$B$147=$A$11)*($C$46:$C$147=E$4)),ROWS(E$11:E12)),"""")"),"Early History Stories") -> Early History Stories | F12: =IFERROR(__xludf.DUMMYFUNCTION("IFERROR(INDEX(FILTER($D$46:$D$147,((($A$46:$A$147=TRUE)+($A$46:$A$147=""☑"")+($A$46:$A$147=""✓"")+($A$46:$A$147=""✔""))>0)*($B$46:$B$147=$A$11)*($C$46:$C$147=F$4)),ROWS(F$11:F12)),"""")"),"") | G12: =IFERROR(__xludf.DUMMYFUNCTION("IFERROR(INDEX(FILTER($D$46:$D$147,((($A$46:$A$147=TRUE)+($A$46:$A$147=""☑"")+($A$46:$A$147=""✓"")+($A$46:$A$147=""✔""))>0)*($B$46:$B$147=$A$11)*($C$46:$C$147=G$4)),ROWS(G$11:G12)),"""")"),"") | H12: =IFERROR(__xludf.DUMMYFUNCTION("IFERROR(INDEX(FILTER($D$46:$D$147,((($A$46:$A$147=TRUE)+($A$46:$A$147=""☑"")+($A$46:$A$147=""✓"")+($A$46:$A$147=""✔""))>0)*($B$46:$B$147=$A$11)*($C$46:$C$147=H$4)),ROWS(H$11:H12)),"""")"),"") | I12: =IFERROR(__xludf.DUMMYFUNCTION("IFERROR(INDEX(FILTER($D$46:$D$147,((($A$46:$A$147=TRUE)+($A$46:$A$147=""☑"")+($A$46:$A$147=""✓"")+($A$46:$A$147=""✔""))>0)*($B$46:$B$147=$A$11)*($C$46:$C$147=I$4)),ROWS(I$11:I12)),"""")"),"") | J12: =IFERROR(__xludf.DUMMYFUNCTION("IFERROR(INDEX(FILTER($D$46:$D$147,((($A$46:$A$147=TRUE)+($A$46:$A$147=""☑"")+($A$46:$A$147=""✓"")+($A$46:$A$147=""✔""))>0)*($B$46:$B$147=$A$11)*($C$46:$C$147=J$4)),ROWS(J$11:J12)),"""")"),"Handicraft / Work") -> Handicraft / Work | K12: =IFERROR(__xludf.DUMMYFUNCTION("IFERROR(INDEX(FILTER($D$46:$D$147,((($A$46:$A$147=TRUE)+($A$46:$A$147=""☑"")+($A$46:$A$147=""✓"")+($A$46:$A$147=""✔""))>0)*($B$46:$B$147=$A$11)*($C$46:$C$147=K$4)),ROWS(K$11:K12)),"""")"),"")
B13: =IFERROR(__xludf.DUMMYFUNCTION("IFERROR(INDEX(FILTER($D$46:$D$147,((($A$46:$A$147=TRUE)+($A$46:$A$147=""☑"")+($A$46:$A$147=""✓"")+($A$46:$A$147=""✔""))>0)*($B$46:$B$147=$A$11)*($C$46:$C$147=B$4)),ROWS(B$11:B13)),"""")"),"") | C13: =IFERROR(__xludf.DUMMYFUNCTION("IFERROR(INDEX(FILTER($D$46:$D$147,((($A$46:$A$147=TRUE)+($A$46:$A$147=""☑"")+($A$46:$A$147=""✓"")+($A$46:$A$147=""✔""))>0)*($B$46:$B$147=$A$11)*($C$46:$C$147=C$4)),ROWS(C$11:C13)),"""")"),"Oral Narration") -> Oral Narration | D13: =IFERROR(__xludf.DUMMYFUNCTION("IFERROR(INDEX(FILTER($D$46:$D$147,((($A$46:$A$147=TRUE)+($A$46:$A$147=""☑"")+($A$46:$A$147=""✓"")+($A$46:$A$147=""✔""))>0)*($B$46:$B$147=$A$11)*($C$46:$C$147=D$4)),ROWS(D$11:D13)),"""")"),"") | E13: =IFERROR(__xludf.DUMMYFUNCTION("IFERROR(INDEX(FILTER($D$46:$D$147,((($A$46:$A$147=TRUE)+($A$46:$A$147=""☑"")+($A$46:$A$147=""✓"")+($A$46:$A$147=""✔""))>0)*($B$46:$B$147=$A$11)*($C$46:$C$147=E$4)),ROWS(E$11:E13)),"""")"),"") | F13: =IFERROR(__xludf.DUMMYFUNCTION("IFERROR(INDEX(FILTER($D$46:$D$147,((($A$46:$A$147=TRUE)+($A$46:$A$147=""☑"")+($A$46:$A$147=""✓"")+($A$46:$A$147=""✔""))>0)*($B$46:$B$147=$A$11)*($C$46:$C$147=F$4)),ROWS(F$11:F13)),"""")"),"") | G13: =IFERROR(__xludf.DUMMYFUNCTION("IFERROR(INDEX(FILTER($D$46:$D$147,((($A$46:$A$147=TRUE)+($A$46:$A$147=""☑"")+($A$46:$A$147=""✓"")+($A$46:$A$147=""✔""))>0)*($B$46:$B$147=$A$11)*($C$46:$C$147=G$4)),ROWS(G$11:G13)),"""")"),"") | H13: =IFERROR(__xludf.DUMMYFUNCTION("IFERROR(INDEX(FILTER($D$46:$D$147,((($A$46:$A$147=TRUE)+($A$46:$A$147=""☑"")+($A$46:$A$147=""✓"")+($A$46:$A$147=""✔""))>0)*($B$46:$B$147=$A$11)*($C$46:$C$147=H$4)),ROWS(H$11:H13)),"""")"),"") | I13: =IFERROR(__xludf.DUMMYFUNCTION("IFERROR(INDEX(FILTER($D$46:$D$147,((($A$46:$A$147=TRUE)+($A$46:$A$147=""☑"")+($A$46:$A$147=""✓"")+($A$46:$A$147=""✔""))>0)*($B$46:$B$147=$A$11)*($C$46:$C$147=I$4)),ROWS(I$11:I13)),"""")"),"") | J13: =IFERROR(__xludf.DUMMYFUNCTION("IFERROR(INDEX(FILTER($D$46:$D$147,((($A$46:$A$147=TRUE)+($A$46:$A$147=""☑"")+($A$46:$A$147=""✓"")+($A$46:$A$147=""✔""))>0)*($B$46:$B$147=$A$11)*($C$46:$C$147=J$4)),ROWS(J$11:J13)),"""")"),"") | K13: =IFERROR(__xludf.DUMMYFUNCTION("IFERROR(INDEX(FILTER($D$46:$D$147,((($A$46:$A$147=TRUE)+($A$46:$A$147=""☑"")+($A$46:$A$147=""✓"")+($A$46:$A$147=""✔""))>0)*($B$46:$B$147=$A$11)*($C$46:$C$147=K$4)),ROWS(K$11:K13)),"""")"),"")
B14: =IFERROR(__xludf.DUMMYFUNCTION("IFERROR(INDEX(FILTER($D$46:$D$147,((($A$46:$A$147=TRUE)+($A$46:$A$147=""☑"")+($A$46:$A$147=""✓"")+($A$46:$A$147=""✔""))>0)*($B$46:$B$147=$A$11)*($C$46:$C$147=B$4)),ROWS(B$11:B14)),"""")"),"") | C14: =IFERROR(__xludf.DUMMYFUNCTION("IFERROR(INDEX(FILTER($D$46:$D$147,((($A$46:$A$147=TRUE)+($A$46:$A$147=""☑"")+($A$46:$A$147=""✓"")+($A$46:$A$147=""✔""))>0)*($B$46:$B$147=$A$11)*($C$46:$C$147=C$4)),ROWS(C$11:C14)),"""")"),"") | D14: =IFERROR(__xludf.DUMMYFUNCTION("IFERROR(INDEX(FILTER($D$46:$D$147,((($A$46:$A$147=TRUE)+($A$46:$A$147=""☑"")+($A$46:$A$147=""✓"")+($A$46:$A$147=""✔""))>0)*($B$46:$B$147=$A$11)*($C$46:$C$147=D$4)),ROWS(D$11:D14)),"""")"),"") | E14: =IFERROR(__xludf.DUMMYFUNCTION("IFERROR(INDEX(FILTER($D$46:$D$147,((($A$46:$A$147=TRUE)+($A$46:$A$147=""☑"")+($A$46:$A$147=""✓"")+($A$46:$A$147=""✔""))>0)*($B$46:$B$147=$A$11)*($C$46:$C$147=E$4)),ROWS(E$11:E14)),"""")"),"") | F14: =IFERROR(__xludf.DUMMYFUNCTION("IFERROR(INDEX(FILTER($D$46:$D$147,((($A$46:$A$147=TRUE)+($A$46:$A$147=""☑"")+($A$46:$A$147=""✓"")+($A$46:$A$147=""✔""))>0)*($B$46:$B$147=$A$11)*($C$46:$C$147=F$4)),ROWS(F$11:F14)),"""")"),"") | G14: =IFERROR(__xludf.DUMMYFUNCTION("IFERROR(INDEX(FILTER($D$46:$D$147,((($A$46:$A$147=TRUE)+($A$46:$A$147=""☑"")+($A$46:$A$147=""✓"")+($A$46:$A$147=""✔""))>0)*($B$46:$B$147=$A$11)*($C$46:$C$147=G$4)),ROWS(G$11:G14)),"""")"),"") | H14: =IFERROR(__xludf.DUMMYFUNCTION("IFERROR(INDEX(FILTER($D$46:$D$147,((($A$46:$A$147=TRUE)+($A$46:$A$147=""☑"")+($A$46:$A$147=""✓"")+($A$46:$A$147=""✔""))>0)*($B$46:$B$147=$A$11)*($C$46:$C$147=H$4)),ROWS(H$11:H14)),"""")"),"") | I14: =IFERROR(__xludf.DUMMYFUNCTION("IFERROR(INDEX(FILTER($D$46:$D$147,((($A$46:$A$147=TRUE)+($A$46:$A$147=""☑"")+($A$46:$A$147=""✓"")+($A$46:$A$147=""✔""))>0)*($B$46:$B$147=$A$11)*($C$46:$C$147=I$4)),ROWS(I$11:I14)),"""")"),"") | J14: =IFERROR(__xludf.DUMMYFUNCTION("IFERROR(INDEX(FILTER($D$46:$D$147,((($A$46:$A$147=TRUE)+($A$46:$A$147=""☑"")+($A$46:$A$147=""✓"")+($A$46:$A$147=""✔""))>0)*($B$46:$B$147=$A$11)*($C$46:$C$147=J$4)),ROWS(J$11:J14)),"""")"),"") | K14: =IFERROR(__xludf.DUMMYFUNCTION("IFERROR(INDEX(FILTER($D$46:$D$147,((($A$46:$A$147=TRUE)+($A$46:$A$147=""☑"")+($A$46:$A$147=""✓"")+($A$46:$A$147=""✔""))>0)*($B$46:$B$147=$A$11)*($C$46:$C$147=K$4)),ROWS(K$11:K14)),"""")"),"")
B15: =IFERROR(__xludf.DUMMYFUNCTION("IFERROR(INDEX(FILTER($D$46:$D$147,((($A$46:$A$147=TRUE)+($A$46:$A$147=""☑"")+($A$46:$A$147=""✓"")+($A$46:$A$147=""✔""))>0)*($B$46:$B$147=$A$11)*($C$46:$C$147=B$4)),ROWS(B$11:B15)),"""")"),"") | C15: =IFERROR(__xludf.DUMMYFUNCTION("IFERROR(INDEX(FILTER($D$46:$D$147,((($A$46:$A$147=TRUE)+($A$46:$A$147=""☑"")+($A$46:$A$147=""✓"")+($A$46:$A$147=""✔""))>0)*($B$46:$B$147=$A$11)*($C$46:$C$147=C$4)),ROWS(C$11:C15)),"""")"),"") | D15: =IFERROR(__xludf.DUMMYFUNCTION("IFERROR(INDEX(FILTER($D$46:$D$147,((($A$46:$A$147=TRUE)+($A$46:$A$147=""☑"")+($A$46:$A$147=""✓"")+($A$46:$A$147=""✔""))>0)*($B$46:$B$147=$A$11)*($C$46:$C$147=D$4)),ROWS(D$11:D15)),"""")"),"") | E15: =IFERROR(__xludf.DUMMYFUNCTION("IFERROR(INDEX(FILTER($D$46:$D$147,((($A$46:$A$147=TRUE)+($A$46:$A$147=""☑"")+($A$46:$A$147=""✓"")+($A$46:$A$147=""✔""))>0)*($B$46:$B$147=$A$11)*($C$46:$C$147=E$4)),ROWS(E$11:E15)),"""")"),"") | F15: =IFERROR(__xludf.DUMMYFUNCTION("IFERROR(INDEX(FILTER($D$46:$D$147,((($A$46:$A$147=TRUE)+($A$46:$A$147=""☑"")+($A$46:$A$147=""✓"")+($A$46:$A$147=""✔""))>0)*($B$46:$B$147=$A$11)*($C$46:$C$147=F$4)),ROWS(F$11:F15)),"""")"),"") | G15: =IFERROR(__xludf.DUMMYFUNCTION("IFERROR(INDEX(FILTER($D$46:$D$147,((($A$46:$A$147=TRUE)+($A$46:$A$147=""☑"")+($A$46:$A$147=""✓"")+($A$46:$A$147=""✔""))>0)*($B$46:$B$147=$A$11)*($C$46:$C$147=G$4)),ROWS(G$11:G15)),"""")"),"") | H15: =IFERROR(__xludf.DUMMYFUNCTION("IFERROR(INDEX(FILTER($D$46:$D$147,((($A$46:$A$147=TRUE)+($A$46:$A$147=""☑"")+($A$46:$A$147=""✓"")+($A$46:$A$147=""✔""))>0)*($B$46:$B$147=$A$11)*($C$46:$C$147=H$4)),ROWS(H$11:H15)),"""")"),"") | I15: =IFERROR(__xludf.DUMMYFUNCTION("IFERROR(INDEX(FILTER($D$46:$D$147,((($A$46:$A$147=TRUE)+($A$46:$A$147=""☑"")+($A$46:$A$147=""✓"")+($A$46:$A$147=""✔""))>0)*($B$46:$B$147=$A$11)*($C$46:$C$147=I$4)),ROWS(I$11:I15)),"""")"),"") | J15: =IFERROR(__xludf.DUMMYFUNCTION("IFERROR(INDEX(FILTER($D$46:$D$147,((($A$46:$A$147=TRUE)+($A$46:$A$147=""☑"")+($A$46:$A$147=""✓"")+($A$46:$A$147=""✔""))>0)*($B$46:$B$147=$A$11)*($C$46:$C$147=J$4)),ROWS(J$11:J15)),"""")"),"") | K15: =IFERROR(__xludf.DUMMYFUNCTION("IFERROR(INDEX(FILTER($D$46:$D$147,((($A$46:$A$147=TRUE)+($A$46:$A$147=""☑"")+($A$46:$A$147=""✓"")+($A$46:$A$147=""✔""))>0)*($B$46:$B$147=$A$11)*($C$46:$C$147=K$4)),ROWS(K$11:K15)),"""")"),"")
A17: Form II | B17: =IFERROR(__xludf.DUMMYFUNCTION("IFERROR(INDEX(FILTER($D$46:$D$147,((($A$46:$A$147=TRUE)+($A$46:$A$147=""☑"")+($A$46:$A$147=""✓"")+($A$46:$A$147=""✔""))>0)*($B$46:$B$147=$A$17)*($C$46:$C$147=B$4)),ROWS(B$17:B17)),"""")"),"") | C17: =IFERROR(__xludf.DUMMYFUNCTION("IFERROR(INDEX(FILTER($D$46:$D$147,((($A$46:$A$147=TRUE)+($A$46:$A$147=""☑"")+($A$46:$A$147=""✓"")+($A$46:$A$147=""✔""))>0)*($B$46:$B$147=$A$17)*($C$46:$C$147=C$4)),ROWS(C$17:C17)),"""")"),"Dictation") -> Dictation | D17: =IFERROR(__xludf.DUMMYFUNCTION("IFERROR(INDEX(FILTER($D$46:$D$147,((($A$46:$A$147=TRUE)+($A$46:$A$147=""☑"")+($A$46:$A$147=""✓"")+($A$46:$A$147=""✔""))>0)*($B$46:$B$147=$A$17)*($C$46:$C$147=D$4)),ROWS(D$17:D17)),"""")"),"Literature") -> Literature | E17: =IFERROR(__xludf.DUMMYFUNCTION("IFERROR(INDEX(FILTER($D$46:$D$147,((($A$46:$A$147=TRUE)+($A$46:$A$147=""☑"")+($A$46:$A$147=""✓"")+($A$46:$A$147=""✔""))>0)*($B$46:$B$147=$A$17)*($C$46:$C$147=E$4)),ROWS(E$17:E17)),"""")"),"History Spine") -> History Spine | F17: =IFERROR(__xludf.DUMMYFUNCTION("IFERROR(INDEX(FILTER($D$46:$D$147,((($A$46:$A$147=TRUE)+($A$46:$A$147=""☑"")+($A$46:$A$147=""✓"")+($A$46:$A$147=""✔""))>0)*($B$46:$B$147=$A$17)*($C$46:$C$147=F$4)),ROWS(F$17:F17)),"""")"),"Geography Reader") -> Geography Reader | G17: =IFERROR(__xludf.DUMMYFUNCTION("IFERROR(INDEX(FILTER($D$46:$D$147,((($A$46:$A$147=TRUE)+($A$46:$A$147=""☑"")+($A$46:$A$147=""✓"")+($A$46:$A$147=""✔""))>0)*($B$46:$B$147=$A$17)*($C$46:$C$147=G$4)),ROWS(G$17:G17)),"""")"),"Citizenship / Plutarch [IIA]") -> Citizenship / Plutarch [IIA] | H17: =IFERROR(__xludf.DUMMYFUNCTION("IFERROR(INDEX(FILTER($D$46:$D$147,((($A$46:$A$147=TRUE)+($A$46:$A$147=""☑"")+($A$46:$A$147=""✓"")+($A$46:$A$147=""✔""))>0)*($B$46:$B$147=$A$17)*($C$46:$C$147=H$4)),ROWS(H$17:H17)),"""")"),"Natural History") -> Natural History | I17: =IFERROR(__xludf.DUMMYFUNCTION("IFERROR(INDEX(FILTER($D$46:$D$147,((($A$46:$A$147=TRUE)+($A$46:$A$147=""☑"")+($A$46:$A$147=""✓"")+($A$46:$A$147=""✔""))>0)*($B$46:$B$147=$A$17)*($C$46:$C$147=I$4)),ROWS(I$17:I17)),"""")"),"Arithmetic") -> Arithmetic | J17: =IFERROR(__xludf.DUMMYFUNCTION("IFERROR(INDEX(FILTER($D$46:$D$147,((($A$46:$A$147=TRUE)+($A$46:$A$147=""☑"")+($A$46:$A$147=""✓"")+($A$46:$A$147=""✔""))>0)*($B$46:$B$147=$A$17)*($C$46:$C$147=J$4)),ROWS(J$17:J17)),"""")"),"") | K17: =IFERROR(__xludf.DUMMYFUNCTION("IFERROR(INDEX(FILTER($D$46:$D$147,((($A$46:$A$147=TRUE)+($A$46:$A$147=""☑"")+($A$46:$A$147=""✓"")+($A$46:$A$147=""✔""))>0)*($B$46:$B$147=$A$17)*($C$46:$C$147=K$4)),ROWS(K$17:K17)),"""")"),"Modern Language") -> Modern Language
B18: =IFERROR(__xludf.DUMMYFUNCTION("IFERROR(INDEX(FILTER($D$46:$D$147,((($A$46:$A$147=TRUE)+($A$46:$A$147=""☑"")+($A$46:$A$147=""✓"")+($A$46:$A$147=""✔""))>0)*($B$46:$B$147=$A$17)*($C$46:$C$147=B$4)),ROWS(B$17:B18)),"""")"),"") | C18: =IFERROR(__xludf.DUMMYFUNCTION("IFERROR(INDEX(FILTER($D$46:$D$147,((($A$46:$A$147=TRUE)+($A$46:$A$147=""☑"")+($A$46:$A$147=""✓"")+($A$46:$A$147=""✔""))>0)*($B$46:$B$147=$A$17)*($C$46:$C$147=C$4)),ROWS(C$17:C18)),"""")"),"Grammar") -> Grammar | D18: =IFERROR(__xludf.DUMMYFUNCTION("IFERROR(INDEX(FILTER($D$46:$D$147,((($A$46:$A$147=TRUE)+($A$46:$A$147=""☑"")+($A$46:$A$147=""✓"")+($A$46:$A$147=""✔""))>0)*($B$46:$B$147=$A$17)*($C$46:$C$147=D$4)),ROWS(D$17:D18)),"""")"),"Shakespeare option") -> Shakespeare option | E18: =IFERROR(__xludf.DUMMYFUNCTION("IFERROR(INDEX(FILTER($D$46:$D$147,((($A$46:$A$147=TRUE)+($A$46:$A$147=""☑"")+($A$46:$A$147=""✓"")+($A$46:$A$147=""✔""))>0)*($B$46:$B$147=$A$17)*($C$46:$C$147=E$4)),ROWS(E$17:E18)),"""")"),"Biography") -> Biography | F18: =IFERROR(__xludf.DUMMYFUNCTION("IFERROR(INDEX(FILTER($D$46:$D$147,((($A$46:$A$147=TRUE)+($A$46:$A$147=""☑"")+($A$46:$A$147=""✓"")+($A$46:$A$147=""✔""))>0)*($B$46:$B$147=$A$17)*($C$46:$C$147=F$4)),ROWS(F$17:F18)),"""")"),"Map Work") -> Map Work | G18: =IFERROR(__xludf.DUMMYFUNCTION("IFERROR(INDEX(FILTER($D$46:$D$147,((($A$46:$A$147=TRUE)+($A$46:$A$147=""☑"")+($A$46:$A$147=""✓"")+($A$46:$A$147=""✔""))>0)*($B$46:$B$147=$A$17)*($C$46:$C$147=G$4)),ROWS(G$17:G18)),"""")"),"") | H18: =IFERROR(__xludf.DUMMYFUNCTION("IFERROR(INDEX(FILTER($D$46:$D$147,((($A$46:$A$147=TRUE)+($A$46:$A$147=""☑"")+($A$46:$A$147=""✓"")+($A$46:$A$147=""✔""))>0)*($B$46:$B$147=$A$17)*($C$46:$C$147=H$4)),ROWS(H$17:H18)),"""")"),"Science") -> Science | I18: =IFERROR(__xludf.DUMMYFUNCTION("IFERROR(INDEX(FILTER($D$46:$D$147,((($A$46:$A$147=TRUE)+($A$46:$A$147=""☑"")+($A$46:$A$147=""✓"")+($A$46:$A$147=""✔""))>0)*($B$46:$B$147=$A$17)*($C$46:$C$147=I$4)),ROWS(I$17:I18)),"""")"),"Practical Geometry") -> Practical Geometry | J18: =IFERROR(__xludf.DUMMYFUNCTION("IFERROR(INDEX(FILTER($D$46:$D$147,((($A$46:$A$147=TRUE)+($A$46:$A$147=""☑"")+($A$46:$A$147=""✓"")+($A$46:$A$147=""✔""))>0)*($B$46:$B$147=$A$17)*($C$46:$C$147=J$4)),ROWS(J$17:J18)),"""")"),"") | K18: =IFERROR(__xludf.DUMMYFUNCTION("IFERROR(INDEX(FILTER($D$46:$D$147,((($A$46:$A$147=TRUE)+($A$46:$A$147=""☑"")+($A$46:$A$147=""✓"")+($A$46:$A$147=""✔""))>0)*($B$46:$B$147=$A$17)*($C$46:$C$147=K$4)),ROWS(K$17:K18)),"""")"),"Latin [IIA]") -> Latin [IIA]
